Traceback (most recent call last):
  File "/Users/emarshall/miniconda3/envs/itslivetools_env/lib/python3.10/site-packages/nbclient/client.py", line 730, in _async_poll_for_reply
    msg = await ensure_async(self.kc.shell_channel.get_msg(timeout=new_timeout))
  File "/Users/emarshall/miniconda3/envs/itslivetools_env/lib/python3.10/site-packages/nbclient/util.py", line 96, in ensure_async
    result = await obj
  File "/Users/emarshall/miniconda3/envs/itslivetools_env/lib/python3.10/site-packages/jupyter_client/channels.py", line 231, in get_msg
    raise Empty
_queue.Empty

During handling of the above exception, another exception occurred:

Traceback (most recent call last):
  File "/Users/emarshall/miniconda3/envs/itslivetools_env/lib/python3.10/site-packages/jupyter_cache/executors/utils.py", line 51, in single_nb_execution
    executenb(
  File "/Users/emarshall/miniconda3/envs/itslivetools_env/lib/python3.10/site-packages/nbclient/client.py", line 1204, in execute
    return NotebookClient(nb=nb, resources=resources, km=km, **kwargs).execute()
  File "/Users/emarshall/miniconda3/envs/itslivetools_env/lib/python3.10/site-packages/nbclient/util.py", line 84, in wrapped
    return just_run(coro(*args, **kwargs))
  File "/Users/emarshall/miniconda3/envs/itslivetools_env/lib/python3.10/site-packages/nbclient/util.py", line 62, in just_run
    return loop.run_until_complete(coro)
  File "/Users/emarshall/miniconda3/envs/itslivetools_env/lib/python3.10/asyncio/base_events.py", line 646, in run_until_complete
    return future.result()
  File "/Users/emarshall/miniconda3/envs/itslivetools_env/lib/python3.10/site-packages/nbclient/client.py", line 663, in async_execute
    await self.async_execute_cell(
  File "/Users/emarshall/miniconda3/envs/itslivetools_env/lib/python3.10/site-packages/nbclient/client.py", line 949, in async_execute_cell
    exec_reply = await self.task_poll_for_reply
  File "/Users/emarshall/miniconda3/envs/itslivetools_env/lib/python3.10/site-packages/nbclient/client.py", line 754, in _async_poll_for_reply
    await self._async_handle_timeout(timeout, cell)
  File "/Users/emarshall/miniconda3/envs/itslivetools_env/lib/python3.10/site-packages/nbclient/client.py", line 801, in _async_handle_timeout
    raise CellTimeoutError.error_from_timeout_and_cell(
nbclient.exceptions.CellTimeoutError: A cell timed out while it was being executed, after 30 seconds.
The message was: Cell execution timed out.
Here is a preview of the cell contents:
-------------------
#compute zonal stats groupedd by ID
grid_mean_sp = grouped_ID.mean(dim=['mid_date','stacked_y_x']).rename({'v': 'speed_mean'}).compute()
grid_min_sp = grouped_ID.min(dim=['mid_date','stacked_y_x']).rename({'v': 'speed_min'}).compute()
grid_max_sp = grouped_ID.max(dim=['mid_date','stacked_y_x']).rename({'v': 'speed_max'}).compute()
grid_std_sp = grouped_ID.std(dim=['mid_date','stacked_y_x']).rename({'v': 'speed_std'}).compute()
    
#merge each zonal stat xr obj into a single xr obj, convert to pandas df
#zonal_stats = xr.merge([grid_mean_sp, grid_min_sp, grid_max_sp, grid_std_sp]).to_dataframe()
#zonal_stats = zonal_stats.reset_index()
#zonal_stats
-------------------

