Traceback (most recent call last):
  File "/Users/emmamarshall/miniconda3/envs/mynewbook/lib/python3.10/site-packages/jupyter_cache/executors/utils.py", line 51, in single_nb_execution
    executenb(
  File "/Users/emmamarshall/miniconda3/envs/mynewbook/lib/python3.10/site-packages/nbclient/client.py", line 1204, in execute
    return NotebookClient(nb=nb, resources=resources, km=km, **kwargs).execute()
  File "/Users/emmamarshall/miniconda3/envs/mynewbook/lib/python3.10/site-packages/nbclient/util.py", line 84, in wrapped
    return just_run(coro(*args, **kwargs))
  File "/Users/emmamarshall/miniconda3/envs/mynewbook/lib/python3.10/site-packages/nbclient/util.py", line 62, in just_run
    return loop.run_until_complete(coro)
  File "/Users/emmamarshall/miniconda3/envs/mynewbook/lib/python3.10/asyncio/base_events.py", line 646, in run_until_complete
    return future.result()
  File "/Users/emmamarshall/miniconda3/envs/mynewbook/lib/python3.10/site-packages/nbclient/client.py", line 663, in async_execute
    await self.async_execute_cell(
  File "/Users/emmamarshall/miniconda3/envs/mynewbook/lib/python3.10/site-packages/nbclient/client.py", line 965, in async_execute_cell
    await self._check_raise_for_error(cell, cell_index, exec_reply)
  File "/Users/emmamarshall/miniconda3/envs/mynewbook/lib/python3.10/site-packages/nbclient/client.py", line 862, in _check_raise_for_error
    raise CellExecutionError.from_cell_and_msg(cell, exec_reply_content)
nbclient.exceptions.CellExecutionError: An error occurred while executing the following cell:
------------------
itslive = rxr.open_rasterio(gen_path + 'HMA_G0120_0000.nc').squeeze()
------------------

[0;31m---------------------------------------------------------------------------[0m
[0;31mKeyError[0m                                  Traceback (most recent call last)
File [0;32m~/miniconda3/envs/mynewbook/lib/python3.10/site-packages/xarray/backends/file_manager.py:199[0m, in [0;36mCachingFileManager._acquire_with_cache_info[0;34m(self, needs_lock)[0m
[1;32m    198[0m [38;5;28;01mtry[39;00m:
[0;32m--> 199[0m     file [38;5;241m=[39m [38;5;28;43mself[39;49m[38;5;241;43m.[39;49m[43m_cache[49m[43m[[49m[38;5;28;43mself[39;49m[38;5;241;43m.[39;49m[43m_key[49m[43m][49m
[1;32m    200[0m [38;5;28;01mexcept[39;00m [38;5;167;01mKeyError[39;00m:

File [0;32m~/miniconda3/envs/mynewbook/lib/python3.10/site-packages/xarray/backends/lru_cache.py:53[0m, in [0;36mLRUCache.__getitem__[0;34m(self, key)[0m
[1;32m     52[0m [38;5;28;01mwith[39;00m [38;5;28mself[39m[38;5;241m.[39m_lock:
[0;32m---> 53[0m     value [38;5;241m=[39m [38;5;28;43mself[39;49m[38;5;241;43m.[39;49m[43m_cache[49m[43m[[49m[43mkey[49m[43m][49m
[1;32m     54[0m     [38;5;28mself[39m[38;5;241m.[39m_cache[38;5;241m.[39mmove_to_end(key)

[0;31mKeyError[0m: [<function open at 0x14b65ec20>, ('/Users/emarshall/Desktop/siparcs/data/HMA_G0120_0000.nc',), 'r', (('sharing', False),)]

During handling of the above exception, another exception occurred:

[0;31mCPLE_OpenFailedError[0m                      Traceback (most recent call last)
File [0;32mrasterio/_base.pyx:261[0m, in [0;36mrasterio._base.DatasetBase.__init__[0;34m()[0m

File [0;32mrasterio/_shim.pyx:78[0m, in [0;36mrasterio._shim.open_dataset[0;34m()[0m

File [0;32mrasterio/_err.pyx:216[0m, in [0;36mrasterio._err.exc_wrap_pointer[0;34m()[0m

[0;31mCPLE_OpenFailedError[0m: /Users/emarshall/Desktop/siparcs/data/HMA_G0120_0000.nc: No such file or directory

During handling of the above exception, another exception occurred:

[0;31mRasterioIOError[0m                           Traceback (most recent call last)
Input [0;32mIn [4][0m, in [0;36m<cell line: 1>[0;34m()[0m
[0;32m----> 1[0m itslive [38;5;241m=[39m [43mrxr[49m[38;5;241;43m.[39;49m[43mopen_rasterio[49m[43m([49m[43mgen_path[49m[43m [49m[38;5;241;43m+[39;49m[43m [49m[38;5;124;43m'[39;49m[38;5;124;43mHMA_G0120_0000.nc[39;49m[38;5;124;43m'[39;49m[43m)[49m[38;5;241m.[39msqueeze()

File [0;32m~/miniconda3/envs/mynewbook/lib/python3.10/site-packages/rioxarray/_io.py:843[0m, in [0;36mopen_rasterio[0;34m(filename, parse_coordinates, chunks, cache, lock, masked, mask_and_scale, variable, group, default_name, decode_times, decode_timedelta, **open_kwargs)[0m
[1;32m    841[0m     [38;5;28;01melse[39;00m:
[1;32m    842[0m         manager [38;5;241m=[39m URIManager(rasterio[38;5;241m.[39mopen, filename, mode[38;5;241m=[39m[38;5;124m"[39m[38;5;124mr[39m[38;5;124m"[39m, kwargs[38;5;241m=[39mopen_kwargs)
[0;32m--> 843[0m     riods [38;5;241m=[39m [43mmanager[49m[38;5;241;43m.[39;49m[43macquire[49m[43m([49m[43m)[49m
[1;32m    844[0m     captured_warnings [38;5;241m=[39m rio_warnings[38;5;241m.[39mcopy()
[1;32m    846[0m [38;5;66;03m# raise the NotGeoreferencedWarning if applicable[39;00m

File [0;32m~/miniconda3/envs/mynewbook/lib/python3.10/site-packages/xarray/backends/file_manager.py:181[0m, in [0;36mCachingFileManager.acquire[0;34m(self, needs_lock)[0m
[1;32m    166[0m [38;5;28;01mdef[39;00m [38;5;21macquire[39m([38;5;28mself[39m, needs_lock[38;5;241m=[39m[38;5;28;01mTrue[39;00m):
[1;32m    167[0m     [38;5;124;03m"""Acquire a file object from the manager.[39;00m
[1;32m    168[0m 
[1;32m    169[0m [38;5;124;03m    A new file is only opened if it has expired from the[39;00m
[0;32m   (...)[0m
[1;32m    179[0m [38;5;124;03m        An open file object, as returned by ``opener(*args, **kwargs)``.[39;00m
[1;32m    180[0m [38;5;124;03m    """[39;00m
[0;32m--> 181[0m     file, _ [38;5;241m=[39m [38;5;28;43mself[39;49m[38;5;241;43m.[39;49m[43m_acquire_with_cache_info[49m[43m([49m[43mneeds_lock[49m[43m)[49m
[1;32m    182[0m     [38;5;28;01mreturn[39;00m file

File [0;32m~/miniconda3/envs/mynewbook/lib/python3.10/site-packages/xarray/backends/file_manager.py:205[0m, in [0;36mCachingFileManager._acquire_with_cache_info[0;34m(self, needs_lock)[0m
[1;32m    203[0m     kwargs [38;5;241m=[39m kwargs[38;5;241m.[39mcopy()
[1;32m    204[0m     kwargs[[38;5;124m"[39m[38;5;124mmode[39m[38;5;124m"[39m] [38;5;241m=[39m [38;5;28mself[39m[38;5;241m.[39m_mode
[0;32m--> 205[0m file [38;5;241m=[39m [38;5;28;43mself[39;49m[38;5;241;43m.[39;49m[43m_opener[49m[43m([49m[38;5;241;43m*[39;49m[38;5;28;43mself[39;49m[38;5;241;43m.[39;49m[43m_args[49m[43m,[49m[43m [49m[38;5;241;43m*[39;49m[38;5;241;43m*[39;49m[43mkwargs[49m[43m)[49m
[1;32m    206[0m [38;5;28;01mif[39;00m [38;5;28mself[39m[38;5;241m.[39m_mode [38;5;241m==[39m [38;5;124m"[39m[38;5;124mw[39m[38;5;124m"[39m:
[1;32m    207[0m     [38;5;66;03m# ensure file doesn't get overridden when opened again[39;00m
[1;32m    208[0m     [38;5;28mself[39m[38;5;241m.[39m_mode [38;5;241m=[39m [38;5;124m"[39m[38;5;124ma[39m[38;5;124m"[39m

File [0;32m~/miniconda3/envs/mynewbook/lib/python3.10/site-packages/rasterio/env.py:437[0m, in [0;36mensure_env_with_credentials.<locals>.wrapper[0;34m(*args, **kwds)[0m
[1;32m    434[0m     session [38;5;241m=[39m DummySession()
[1;32m    436[0m [38;5;28;01mwith[39;00m env_ctor(session[38;5;241m=[39msession):
[0;32m--> 437[0m     [38;5;28;01mreturn[39;00m [43mf[49m[43m([49m[38;5;241;43m*[39;49m[43margs[49m[43m,[49m[43m [49m[38;5;241;43m*[39;49m[38;5;241;43m*[39;49m[43mkwds[49m[43m)[49m

File [0;32m~/miniconda3/envs/mynewbook/lib/python3.10/site-packages/rasterio/__init__.py:220[0m, in [0;36mopen[0;34m(fp, mode, driver, width, height, count, crs, transform, dtype, nodata, sharing, **kwargs)[0m
[1;32m    216[0m [38;5;66;03m# Create dataset instances and pass the given env, which will[39;00m
[1;32m    217[0m [38;5;66;03m# be taken over by the dataset's context manager if it is not[39;00m
[1;32m    218[0m [38;5;66;03m# None.[39;00m
[1;32m    219[0m [38;5;28;01mif[39;00m mode [38;5;241m==[39m [38;5;124m'[39m[38;5;124mr[39m[38;5;124m'[39m:
[0;32m--> 220[0m     s [38;5;241m=[39m [43mDatasetReader[49m[43m([49m[43mpath[49m[43m,[49m[43m [49m[43mdriver[49m[38;5;241;43m=[39;49m[43mdriver[49m[43m,[49m[43m [49m[43msharing[49m[38;5;241;43m=[39;49m[43msharing[49m[43m,[49m[43m [49m[38;5;241;43m*[39;49m[38;5;241;43m*[39;49m[43mkwargs[49m[43m)[49m
[1;32m    221[0m [38;5;28;01melif[39;00m mode [38;5;241m==[39m [38;5;124m"[39m[38;5;124mr+[39m[38;5;124m"[39m:
[1;32m    222[0m     s [38;5;241m=[39m get_writer_for_path(path, driver[38;5;241m=[39mdriver)(
[1;32m    223[0m         path, mode, driver[38;5;241m=[39mdriver, sharing[38;5;241m=[39msharing, [38;5;241m*[39m[38;5;241m*[39mkwargs
[1;32m    224[0m     )

File [0;32mrasterio/_base.pyx:263[0m, in [0;36mrasterio._base.DatasetBase.__init__[0;34m()[0m

[0;31mRasterioIOError[0m: /Users/emarshall/Desktop/siparcs/data/HMA_G0120_0000.nc: No such file or directory
RasterioIOError: /Users/emarshall/Desktop/siparcs/data/HMA_G0120_0000.nc: No such file or directory

